<?xml version="1.0" ?>
<robot name="servoarm" xmlns:xacro="http://www.ros.org/wiki/xacro">


    <link name="base_link">
        <visual>
            <geometry>
		<mesh filename="package://armbot_moveit2/config/urdf/meshes/u_type_robot_waist_bracket.stl" scale ="0.013 0.013 0.013"/>
            </geometry>
             <origin rpy="0 1.57 0" xyz="-0.58 0 0"/>
	     <material name="grey"> <color rgba="1 1 1 1"/> </material>
        </visual>
        <collision>
            <geometry>
		<mesh filename="package://armbot_moveit2/config/urdf/meshes/u_type_robot_waist_bracket.stl" scale ="0.013 0.013 0.013"/>
            </geometry>
             <origin rpy="0 1.57 0" xyz="-0.58 0 0"/>
        </collision>
    </link>

    <link name="base_link2">
        <visual>
            <geometry>
		<mesh filename="package://armbot_moveit2/config/urdf/meshes/u_type_robot_waist_bracket.stl" scale ="0.013 0.013 0.013"/>
            </geometry>
             <origin rpy="3.14156 1.57 0" xyz="0.60 0 0"/>
	     <material name="grey"> <color rgba="1 1 1 1"/> </material>
        </visual>
        <collision>
            <geometry>
		<mesh filename="package://armbot_moveit2/config/urdf/meshes/u_type_robot_waist_bracket.stl" scale ="0.013 0.013 0.013"/>
            </geometry>
             <origin rpy="3.14156 1.57 0" xyz="0.60 0 0"/>
        </collision>
    </link>

    <joint name="base_joint_dummy" type="fixed">
        <origin rpy="0 0 0.0" xyz="0 0 0.0" />
        <parent link="base_link" />
        <child link="base_link2" />
        <axis xyz="0 0 0" />
    </joint>



    <link name="platform_bracket">
        <visual>
            <geometry>
		<mesh filename="package://armbot_moveit2/config/urdf/meshes/multi_functional_servo_bracket.stl" scale ="0.013 0.013 0.013"/>
            </geometry>
             <origin rpy="1.57 0  3.14156" xyz="0.1 -0.65  0.2"/>
	     <material name="blue"> <color rgba="0 0 1 1"/> </material>
        </visual>
        <collision>
            <geometry>
		<mesh filename="package://armbot_moveit2/config/urdf/meshes/multi_functional_servo_bracket.stl" scale ="0.013 0.013 0.013"/>
            </geometry>
             <origin rpy="1.57 0  3.14156" xyz="0.1 -0.65  0.2"/>
        </collision>
    </link>


    <link name="platform_servo">
        <visual>
            <geometry>
		    <mesh filename="package://armbot_moveit2/config/urdf/meshes/mg996r_servo.stl" scale ="0.013 0.013 0.013"/>
            </geometry>
             <origin rpy="0 0 3.1415" xyz="0  -0.25  0.2"/>
	     <material name="blue"> <color rgba="0 0 1 1"/> </material>
        </visual>
        <collision>
            <geometry>
		    <mesh filename="package://armbot_moveit2/config/urdf/meshes/mg996r_servo.stl" scale ="0.013 0.013 0.013"/>
            </geometry>
             <origin rpy="0 0 3.1415" xyz="0  -0.25  0.2"/>
        </collision>
    </link>

    <joint name="platform_servo_joint_dummy" type="fixed">
        <origin rpy="0 0 0" xyz="0 0 0.0" />
        <parent link="platform_bracket" />
        <child link="platform_servo" />
        <axis xyz="0 0 0" />
    </joint>


    <joint name="platform_joint_dummy" type="fixed">
        <origin rpy="0 0 0" xyz="0 0 0.0" />
        <parent link="base_link2" />
        <child link="platform_bracket" />
        <axis xyz="0 0 0" />
    </joint>




    <link name="plate_bracket">
        <visual>
            <geometry>
		<mesh filename="package://armbot_moveit2/config/urdf/meshes/multi_functional_servo_bracket.stl" scale ="0.013 0.013 0.013"/>
            </geometry>
             <origin rpy="0 1.57 1.57" xyz="0.2  -0.25  0.15"/>
	     <material name="green"> <color rgba="0 1 0 1"/> </material>
        </visual>
        <collision>
            <geometry>
		<mesh filename="package://armbot_moveit2/config/urdf/meshes/multi_functional_servo_bracket.stl" scale ="0.013 0.013 0.013"/>
            </geometry>
             <origin rpy="0 1.57 1.57" xyz="0.2  -0.25  0.15"/>
        </collision>
    </link>


    <link name="plate_servo">
        <visual>
            <geometry>
		    <mesh filename="package://armbot_moveit2/config/urdf/meshes/mg996r_servo.stl" scale ="0.013 0.013 0.013"/>
            </geometry>
	     <material name="green"> <color rgba="0 1 0 1"/> </material>
             <origin rpy="3.1415 1.57 0" xyz="0.2  0.0  0.05"/>
        </visual>
        <collision>
            <geometry>
		    <mesh filename="package://armbot_moveit2/config/urdf/meshes/mg996r_servo.stl" scale ="0.013 0.013 0.013"/>
            </geometry>
             <origin rpy="3.1415 1.57 0" xyz="0.2 0.0  0.05"/>
        </collision>
    </link>


    <joint name="plate_servo_joint_dummy" type="fixed">
        <origin rpy="0 0 0" xyz="0 0 0.0" />
        <parent link="plate_bracket" />
        <child link="plate_servo" />
        <axis xyz="0 0 0" />
    </joint>


    <joint name="base_joint" type="revolute">
        <safety_controller k_position="100.0" k_velocity="40.0" soft_lower_limit="-1.955" soft_upper_limit="1.955" />
        <limit effort="87" lower="-1.963" upper="1.963" velocity="2.3925" />
        <origin rpy="0 0 0" xyz="0.115 -0.64 0.90" /> <axis xyz="0 0 1" />
        <parent link="platform_servo" />
        <child link="plate_bracket" />
    </joint>





    <link name="lower_arm">
        <visual>
            <geometry>
                <mesh filename="package://armbot_moveit2/config/urdf/meshes/lower_arm.stl" scale ="0.001 0.001 0.001"/>
            </geometry>
	     <material name="grey"> <color rgba="1 1 1 1"/> </material>
        </visual>
        <collision>
            <geometry>
                <mesh filename="package://armbot_moveit2/config/urdf/meshes/lower_arm.stl" scale ="0.001 0.001 0.001"/>
            </geometry>
        </collision>
    </link>



    <joint name="platform_joint" type="revolute">
        <safety_controller k_position="100.0" k_velocity="40.0" soft_lower_limit="-1.955" soft_upper_limit="1.955" />
        <limit effort="87" lower="-1.963" upper="1.963" velocity="2.3925" />
	<!---
        <origin rpy="1.31 0 0" xyz="-0.045 -0.125 0.055"/> <axis xyz="-1 0 0" />
	-->
        <origin rpy="1.95 0 0" xyz="-0.045 -0.125 0.055"/> <axis xyz="-1 0 0" />
        <parent link="plate_servo" />
        <child link="lower_arm" />
    </joint>



    <link name="top_arm">
        <visual>
            <geometry>
	    <mesh filename="package://armbot_moveit2/config/urdf/meshes/top_arm.stl" scale ="0.001 0.001 0.001"/>
            </geometry>
              <origin rpy="0 1.59 0" xyz="0 0 0"/>
	     <material name="grey"> <color rgba="1 1 1 1"/> </material>
        </visual>
        <collision>
            <geometry>
	    <mesh filename="package://armbot_moveit2/config/urdf/meshes/top_arm.stl" scale ="0.001 0.001 0.001"/>
            </geometry>
              <origin rpy="0 1.59 0" xyz="0 0 0"/>
        </collision>
    </link>

    <joint name="lower_joint" type="revolute">
        <safety_controller k_position="100.0" k_velocity="40.0" soft_lower_limit="-1.955" soft_upper_limit="1.955" />
        <limit effort="87" lower="-1.963" upper="1.963" velocity="2.3925" />
        <origin rpy="-0.35 0 0" xyz="-0.23 1.02 0.015"/> <axis xyz="1 0 0" />
        <parent link="lower_arm" />
        <child link="top_arm" />
    </joint>




    <link name="wrist">
        <visual>
            <geometry>
		    <mesh filename="package://armbot_moveit2/config/urdf/meshes/wrist.stl" scale ="0.001 0.001 0.001"/>
            </geometry>
	     <material name="blue"> <color rgba="0 0 1 1"/> </material>
        </visual>
        <collision>
            <geometry>
		    <mesh filename="package://armbot_moveit2/config/urdf/meshes/wrist.stl" scale ="0.001 0.001 0.001"/>
            </geometry>
        </collision>
    </link>


    <joint name="top_joint" type="revolute">
        <safety_controller k_position="100.0" k_velocity="40.0" soft_lower_limit="-1.955" soft_upper_limit="1.955" />
        <limit effort="87" lower="-1.963" upper="1.963" velocity="2.3925" />
        <parent link="top_arm" />
        <child link="wrist" />

	<!--
	<origin xyz="0.09 1.25 0"/> <axis xyz="-1 0 0" />
	0.34906222222222222221 .41886666666666666665
	<origin rpy="-0.418 0 0" xyz="0.09 1.25 0"/> <axis xyz="-1 0 0" />
	-->
	<origin rpy="-0.218 0 0" xyz="0.09 1.25 0"/> <axis xyz="-1 0 0" />

    </joint>


    <link name="eef_link" />

    <joint name="eef_joint" type="revolute">
        <safety_controller k_position="100.0" k_velocity="40.0" soft_lower_limit="-1.955" soft_upper_limit="1.955" />
        <limit effort="87" lower="-1.963" upper="1.963" velocity="2.3925" />
        <origin xyz="0 0.63 0"/>
        <parent link="wrist" />
        <child link="eef_link" />
	<axis xyz="0 1 0" />
    </joint>


    <link name="clawbase">
        <visual>
            <geometry>
		    <mesh filename="package://armbot_moveit2/config/urdf/meshes/clawbase.stl" scale ="0.001 0.001 0.001"/>

            </geometry>
            <origin rpy="0 0 0" xyz="0 0 0" />
	    <material name="grey"> </material>
        </visual>
        <collision>
            <geometry>
		    <mesh filename="package://armbot_moveit2/config/urdf/meshes/clawbase.stl" scale ="0.001 0.001 0.001"/>
            </geometry>
        </collision>
    </link>


   <joint name="hand_joint" type="fixed">
        <parent link="eef_link" />
        <child link="clawbase" />
        <origin rpy="0 0 0.0" xyz="0 0 0" />
        <axis xyz="0 0 0" />
    </joint>



    <link name="clawl">
        <visual>
            <geometry>
	      <mesh filename="package://armbot_moveit2/config/urdf/meshes/clawl.stl" scale ="0.001 0.001 0.001"/>
            </geometry>
	      <material name="green"> </material>
        </visual>
        <collision>
            <geometry>
		    <mesh filename="package://armbot_moveit2/config/urdf/meshes/clawl.stl" scale ="0.001 0.001 0.001"/>
            </geometry>
        </collision>
    </link>

    <link name="clawr">
        <visual>
            <geometry>
		    <mesh filename="package://armbot_moveit2/config/urdf/meshes/clawr.stl" scale ="0.001 0.001 0.001"/>
            </geometry>
	    <material name="green"> </material>
        </visual>
        <collision>
            <geometry>
		    <mesh filename="package://armbot_moveit2/config/urdf/meshes/clawr.stl" scale ="0.001 0.001 0.001"/>
            </geometry>
        </collision>
    </link>


    <joint name="clawl_joint" type="revolute">
        <parent link="clawbase" />
        <child link="clawl" />
        <origin rpy="0 0 1.77" xyz="-0.142 0.305 -0.05"/> <axis xyz="0 0 -1" />
	<!--
        <limit effort="87" lower="0.0" upper="0.4" velocity="0.2" />
        <safety_controller k_position="100.0" k_velocity="40.0" soft_lower_limit="-0.01" soft_upper_limit="0.41" />
	-->
        <limit effort="87" lower="0.611" upper="1.57" velocity="2.3925" />
        <safety_controller k_position="100.0" k_velocity="40.0" soft_lower_limit="0.611" soft_upper_limit="1.57" />
    </joint>

    <joint name="clawr_joint" type="revolute">
        <parent link="clawbase" />
        <child link="clawr" />
        <origin rpy="0 0 -1.97" xyz="0.152 0.305 -0.05"/> <axis xyz="0 0 -1" />
        <mimic joint="clawl_joint" multiplier="-1" offset="0" />
	<!--
        <limit effort="87" lower="-0.4" upper="0.0" velocity="0.2" />
        <safety_controller k_position="100.0" k_velocity="40.0" soft_lower_limit="-0.41" soft_upper_limit="0.01" />
	-->
        <limit effort="87" lower="-1.57" upper="-0.611" velocity="2.3925" />
        <safety_controller k_position="100.0" k_velocity="40.0" soft_lower_limit="-1.57" soft_upper_limit="-0.611" />
    </joint>


</robot>
