<?xml version="1.0" ?>
<robot name="servoarm" xmlns:xacro="http://www.ros.org/wiki/xacro">


    <link name="base_link">
        <visual>
            <geometry>
		    <mesh filename="package://armbot_moveit2/config/urdf/meshes/base_cylinder.stl" scale ="0.0001 0.0001 0.0001"/>
		<!--
                <mesh filename="file:///ros2/prows/urdf/servoarm_description/meshes/base_cylinder_simple.stl" scale ="0.01 0.01 0.01"/>
                <mesh filename="package://moveit_resources_panda_description/meshes/visual/link0.dae" />
		-->
            </geometry>
        </visual>
        <collision>
            <geometry>
		    <mesh filename="package://armbot_moveit2/config/urdf/meshes/base_cylinder.stl" scale ="0.0001 0.0001 0.0001"/>
		<!--
                <mesh filename="package://moveit_resources_panda_description/meshes/collision/link0.stl" />
		-->
            </geometry>
        </collision>
    </link>
    <link name="platform">
        <visual>
            <geometry>
		    <!--
                <mesh filename="package://moveit_resources_panda_description/meshes/visual/link1.dae" />
		    -->
                <mesh filename="file:///ros2/prows/urdf/servoarm_description/meshes/top_plate.stl" scale ="0.001 0.001 0.001"/>

            </geometry>
        </visual>
        <collision>
            <geometry>
		    <!--
                <mesh filename="package://moveit_resources_panda_description/meshes/collision/link1.stl" />
		    -->
		<mesh filename="package://armbot_moveit2/config/urdf/meshes/top_plate.stl" scale ="0.001 0.001 0.001"/>
            </geometry>
        </collision>
    </link>


    <joint name="base_joint" type="revolute">
        <safety_controller k_position="100.0" k_velocity="40.0" soft_lower_limit="-2.33" soft_upper_limit="2.33" />
        <limit effort="87" lower="-2.34" upper="2.34" velocity="2.3925" />
        <origin rpy="0 0 0" xyz="0 0 0.48" />
        <parent link="base_link" />
        <child link="platform" />
        <axis xyz="0 0 1" />
    </joint>


    <link name="lower_arm">
        <visual>
            <geometry>
		    <!--
                <mesh filename="package://moveit_resources_panda_description/meshes/visual/link2.dae" />
		    -->
		<mesh filename="package://armbot_moveit2/config/urdf/meshes/lower_arm.stl" scale ="0.001 0.001 0.001"/>

            </geometry>
        </visual>
        <collision>
            <geometry>
		    <!--
                <mesh filename="package://moveit_resources_panda_description/meshes/collision/link2.stl" />
		    -->
		<mesh filename="package://armbot_moveit2/config/urdf/meshes/lower_arm.stl" scale ="0.001 0.001 0.001"/>
            </geometry>
        </collision>
    </link>
    <joint name="platform_joint" type="revolute">
        <safety_controller k_position="100.0" k_velocity="40.0" soft_lower_limit="-2.33" soft_upper_limit="2.33" />
        <limit effort="87" lower="-2.34" upper="2.34" velocity="2.3925" />
        <origin xyz="0 0.19 0.28"/> <axis xyz="1 0 0" />
        <parent link="platform" />
        <child link="lower_arm" />
    </joint>



    <link name="top_arm">
        <visual>
            <geometry>
		    <mesh filename="package://armbot_moveit2/config/urdf/meshes/top_arm.stl" scale ="0.001 0.001 0.001"/>
            </geometry>
              <origin rpy="0 1.59 0" xyz="0 0 0"/>
        </visual>
        <collision>
            <geometry>
		    <mesh filename="package://armbot_moveit2/config/urdf/meshes/top_arm.stl" scale ="0.001 0.001 0.001"/>
            </geometry>
              <origin rpy="0 1.59 0" xyz="0 0 0"/>
        </collision>
    </link>

    <joint name="lower_joint" type="revolute">
        <safety_controller k_position="100.0" k_velocity="40.0" soft_lower_limit="-2.33" soft_upper_limit="2.33" />
        <limit effort="87" lower="-2.34" upper="2.34" velocity="2.3925" />
        <origin xyz="-0.25 1.0 0"/> <axis xyz="1 0 0" />
        <parent link="lower_arm" />
        <child link="top_arm" />
    </joint>


    <link name="wrist">
        <visual>
            <geometry>
		    <mesh filename="package://armbot_moveit2/config/urdf/meshes/wrist.stl" scale ="0.001 0.001 0.001"/>
            </geometry>
	    <material name="blue">
              <color rgba="0 1 0 1"/>
            </material>

        </visual>
        <collision>
            <geometry>
		    <mesh filename="package://armbot_moveit2/config/urdf/meshes/wrist.stl" scale ="0.001 0.001 0.001"/>
            </geometry>
        </collision>
    </link>


    <joint name="top_joint" type="revolute">
        <safety_controller k_position="100.0" k_velocity="40.0" soft_lower_limit="-2.33" soft_upper_limit="2.33" />
        <limit effort="87" lower="-2.34" upper="2.34" velocity="2.3925" />
        <parent link="top_arm" />
        <child link="wrist" />
	<origin xyz="0.11 1.25 0"/> <axis xyz="1 0 0" />
    </joint>

    <!--
    <link name="dummy" />

    <joint name="dummy_joint" type="fixed">
        <origin xyz="0 0.0 0"/>
        <parent link="wrist" />
        <child link="dummy" />
        <axis xyz="0 0 0" />
    </joint>
    -->



    <link name="eef_link" />


    <joint name="eef_joint" type="fixed">
        <origin xyz="0 0.63 0"/>
        <parent link="wrist" />
        <child link="eef_link" />
        <axis xyz="0 0 0" />
    </joint>


   <joint name="hand_joint" type="revolute">
        <safety_controller k_position="100.0" k_velocity="40.0" soft_lower_limit="-2.33" soft_upper_limit="2.33" />
        <limit effort="87" lower="-2.34" upper="2.34" velocity="2.3925" />
        <parent link="eef_link" />
        <child link="clawbase" />
        <origin rpy="0 0 0.0" xyz="0 0 0" />
	<axis xyz="0 1 0" />
    </joint>


    <link name="clawbase">
        <visual>
            <geometry>
		    <mesh filename="package://armbot_moveit2/config/urdf/meshes/clawbase.stl" scale ="0.001 0.001 0.001"/>

            </geometry>
            <origin rpy="0 0 0" xyz="0 0 0" />
	    <material name="white">
               <color rgba="1 1 1 1"/>
            </material>
        </visual>
        <collision>
            <geometry>
		    <mesh filename="package://armbot_moveit2/config/urdf/meshes/clawbase.stl" scale ="0.001 0.001 0.001"/>
            </geometry>
        </collision>
    </link>



    <link name="clawl">
        <visual>
            <geometry>
		    <mesh filename="package://armbot_moveit2/config/urdf/meshes/clawl.stl" scale ="0.001 0.001 0.001"/>

            </geometry>
        </visual>
        <collision>
            <geometry>
		    <mesh filename="package://armbot_moveit2/config/urdf/meshes/clawl.stl" scale ="0.001 0.001 0.001"/>
            </geometry>
        </collision>
    </link>

    <link name="clawr">
        <visual>
            <geometry>
		    <mesh filename="package://armbot_moveit2/config/urdf/meshes/clawr.stl" scale ="0.001 0.001 0.001"/>
            </geometry>
        </visual>
        <collision>
            <geometry>
		    <mesh filename="package://armbot_moveit2/config/urdf/meshes/clawr.stl" scale ="0.001 0.001 0.001"/>
            </geometry>
        </collision>
    </link>


    <joint name="clawl_joint" type="revolute">
        <parent link="clawbase" />
        <child link="clawl" />
        <origin rpy="0 0 0.31" xyz="-0.142 0.305 -0.05"/> <axis xyz="0 0 1" />
        <limit effort="87" lower="0.0" upper="0.4" velocity="0.2" />
    </joint>

    <joint name="clawr_joint" type="revolute">
        <parent link="clawbase" />
        <child link="clawr" />
        <origin rpy="0 0 -0.31" xyz="0.152 0.305 -0.05"/> <axis xyz="0 0 1" />
        <limit effort="87" lower="-0.4" upper="0.0" velocity="0.2" />
        <mimic joint="clawl_joint" multiplier="-1" offset="0" />
    </joint>



</robot>
